<?xml version="1.0" ?>
<robot name="robot-arm">
  
  <link name="Base">
    <visual name="Base_visual">
      <origin xyz="0 0 0" rpy="0 0 0"/>
      <geometry>
        <mesh filename="meshes/Base.stl"/>
      </geometry>
      <material name="Base-material">
        <color rgba="1 0.5 0 1"/>
      </material>
    </visual>
    <collision name="Base_collision">
      <origin xyz="0 0 0" rpy="0 0 0"/>
      <geometry>
        <mesh filename="meshes/Base.stl"/>
      </geometry>
    </collision>
    <inertial>
      <mass value="0.22579514"/>
      <inertia ixx="0.0002840554" iyy="0.00067185635" izz="0.00082391455" ixy="3.756062e-06" ixz="4.8717476e-06" iyz="4.1491839e-07"/>
      <origin xyz="-0.041913942 0.00047418564 0.023219926" rpy="0 0 0"/>
    </inertial>
  </link>
  <link name="Link_1">
    <visual name="Link_1_visual">
      <origin xyz="0 0 0" rpy="0 0 0"/>
      <geometry>
        <mesh filename="meshes/Link_1.stl"/>
      </geometry>
      <material name="Link_1-material">
        <color rgba="1 0.5 0 1"/>
      </material>
    </visual>
    <collision name="Link_1_collision">
      <origin xyz="0 0 0" rpy="0 0 0"/>
      <geometry>
        <mesh filename="meshes/Link_1.stl"/>
      </geometry>
    </collision>
    <inertial>
      <mass value="0.1676629"/>
      <inertia ixx="0.00012301676" iyy="0.00011376972" izz="0.00011253315" ixy="2.597404e-11" ixz="-1.6580186e-12" iyz="-1.8085889e-05"/>
      <origin xyz="-6.7148366e-09 0.013086455 0.024697496" rpy="0 0 0"/>
    </inertial>
  </link>
  <link name="Link_2">
    <visual name="Link_2_visual">
      <origin xyz="0 0 0" rpy="0 0 0"/>
      <geometry>
        <mesh filename="meshes/Link_2.stl"/>
      </geometry>
      <material name="Link_2-material">
        <color rgba="1 1 0 1"/>
      </material>
    </visual>
    <collision name="Link_2_collision">
      <origin xyz="0 0 0" rpy="0 0 0"/>
      <geometry>
        <mesh filename="meshes/Link_2.stl"/>
      </geometry>
    </collision>
    <inertial>
      <mass value="0.16402824"/>
      <inertia ixx="3.6764159e-05" iyy="0.00047216039" izz="0.00049435452" ixy="-2.1050301e-11" ixz="1.2372685e-10" iyz="2.2105373e-11"/>
      <origin xyz="0.069999939 -3.7796082e-08 -0.010449721" rpy="0 0 0"/>
    </inertial>
  </link>
  <link name="Link_3">
    <visual name="Link_3_visual">
      <origin xyz="0 0 0" rpy="0 0 0"/>
      <geometry>
        <mesh filename="meshes/Link_3.stl"/>
      </geometry>
      <material name="Link_3-material">
        <color rgba="1 0 0.5 1"/>
      </material>
    </visual>
    <collision name="Link_3_collision">
      <origin xyz="0 0 0" rpy="0 0 0"/>
      <geometry>
        <mesh filename="meshes/Link_3.stl"/>
      </geometry>
    </collision>
    <inertial>
      <mass value="0.14621308"/>
      <inertia ixx="3.4457565e-05" iyy="0.00025909398" izz="0.00025063291" ixy="-9.2393348e-11" ixz="1.5915992e-05" iyz="-3.6605326e-11"/>
      <origin xyz="0.037648116 2.13735e-08 0.014993859" rpy="0 0 0"/>
    </inertial>
  </link>
  <link name="Link_4">
    <visual name="Link_4_visual">
      <origin xyz="0 0 0" rpy="0 0 0"/>
      <geometry>
        <mesh filename="meshes/Link_4.stl"/>
      </geometry>
      <material name="Link_4-material">
        <color rgba="0 1 0 1"/>
      </material>
    </visual>
    <collision name="Link_4_collision">
      <origin xyz="0 0 0" rpy="0 0 0"/>
      <geometry>
        <mesh filename="meshes/Link_4.stl"/>
      </geometry>
    </collision>
    <inertial>
      <mass value="0.042804316"/>
      <inertia ixx="6.7480551e-06" iyy="1.0763083e-05" izz="1.154155e-05" ixy="-2.5718329e-08" ixz="-2.5823274e-08" iyz="1.4883063e-09"/>
      <origin xyz="4.7393257e-05 -2.0656562e-05 -0.012253257" rpy="0 0 0"/>
    </inertial>
  </link>
  <link name="End_Effector">
    <visual name="End_Effector_visual">
      <origin xyz="0 0 0" rpy="0 0 0"/>
      <geometry>
        <mesh filename="meshes/End_Effector.stl"/>
      </geometry>
      <material name="End_Effector-material">
        <color rgba="0 0 0 1"/>
      </material>
    </visual>
    <collision name="End_Effector_collision">
      <origin xyz="0 0 0" rpy="0 0 0"/>
      <geometry>
        <mesh filename="meshes/End_Effector.stl"/>
      </geometry>
    </collision>
    <inertial>
      <mass value="0.052276675"/>
      <inertia ixx="3.4675475e-05" iyy="4.9430077e-05" izz="2.1041401e-05" ixy="8.9031668e-07" ixz="-1.325108e-06" iyz="1.7164732e-06"/>
      <origin xyz="-0.0012587778 -0.0012464139 0.02979157" rpy="0 0 0"/>
    </inertial>
  </link>
  <joint name="joint" type="revolute">
    <origin xyz="0 0 0.05" rpy="0 0 1.5707963"/>
    <parent link="Base"/>
    <child link="Link_1"/>
    <axis xyz="0 0 1"/>
    <limit effort="1" velocity="1" lower="-1.57079611" upper="1.57079611"/>
  </joint>
  <joint name="joint-1" type="revolute">
    <origin xyz="-3.2706323e-09 0.00099697 0.043550108" rpy="-1.5707963 -1.5707963 0"/>
    <parent link="Link_1"/>
    <child link="Link_2"/>
    <axis xyz="0 0 1"/>
    <limit effort="1" velocity="1" lower="-1.57079633" upper="1.57079633"/>
  </joint>
  <joint name="joint-2" type="revolute">
    <origin xyz="0.14 0 0" rpy="0 0 0"/>
    <parent link="Link_2"/>
    <child link="Link_3"/>
    <axis xyz="0 0 1"/>
    <limit effort="1" velocity="1" lower="-0.78539816" upper="2.35619449"/>
  </joint>
  <joint name="joint-3" type="revolute">
    <origin xyz="0.10575011 -3.2706325e-09 -0.0015" rpy="5.8286709e-15 -2.220446e-16 -1.2799832e-24"/>
    <parent link="Link_3"/>
    <child link="Link_4"/>
    <axis xyz="0 0 1"/>
    <limit effort="1" velocity="1" lower="-0.78539816" upper="2.35619449"/>
  </joint>
  <joint name="joint-4" type="revolute">
    <origin xyz="0.02345 0.0051499978 -0.012" rpy="1.5707963 -1.8429702e-14 1.5707963"/>
    <parent link="Link_4"/>
    <child link="End_Effector"/>
    <axis xyz="0 0 1"/>
    <limit effort="1" velocity="1" lower="-1.57079633" upper="1.57079633"/>
  </joint>
</robot>
